<?xml version="1.0" encoding="utf-8"?>
<!-- This URDF was automatically created by SolidWorks to URDF Exporter! Originally created by Stephen Brawner (brawner@gmail.com) 
     Commit Version: 1.6.0-1-g15f4949  Build Version: 1.6.7594.29634
     For more information, please see http://wiki.ros.org/sw_urdf_exporter -->
<robot
  name="GRD_URDF_v8_material">
  <link
    name="base_footprint_link">
    <inertial>
      <origin
        xyz="-6.5684535257726E-07 -5.68625826943039E-16 0.331904075260688"
        rpy="0 0 0" />
      <mass
        value="0.94714877441203" />
      <inertia
        ixx="0.00156805076680093"
        ixy="-4.04417685042527E-18"
        ixz="-1.07156180552169E-09"
        iyy="0.00467978185671069"
        iyz="1.05204051443102E-18"
        izz="0.00464373853240198" />
    </inertial>
    <visual>
      <origin
        xyz="0 0 0"
        rpy="0 0 0" />
      <geometry>
        <mesh
          filename="package://GRD_URDF_v8_material/meshes/base_footprint_link.STL" />
      </geometry>
      <material
        name="">
        <color
          rgba="1 1 1 0.3" />
      </material>
    </visual>
    <collision>
      <origin
        xyz="0 0 0"
        rpy="0 0 0" />
      <geometry>
        <mesh
          filename="package://GRD_URDF_v8_material/meshes/base_footprint_link.STL" />
      </geometry>
    </collision>
  </link>
  <link
    name="base_link">
    <inertial>
      <origin
        xyz="-5.37004284930829E-07 -8.85973754038104E-16 0.0331211817986433"
        rpy="0 0 0" />
      <mass
        value="1.15852013355761" />
      <inertia
        ixx="0.00161866128869471"
        ixy="-4.05306861158348E-18"
        ixz="-1.07156180552086E-09"
        iyy="0.00471344940362746"
        iyz="1.05084288143918E-18"
        izz="0.00470124275078615" />
    </inertial>
    <visual>
      <origin
        xyz="0 0 0"
        rpy="0 0 0" />
      <geometry>
        <mesh
          filename="package://GRD_URDF_v8_material/meshes/base_link.STL" />
      </geometry>
      <material
        name="">
        <color
          rgba="1 1 1 0.3" />
      </material>
    </visual>
    <collision>
      <origin
        xyz="0 0 0"
        rpy="0 0 0" />
      <geometry>
        <mesh
          filename="package://GRD_URDF_v8_material/meshes/base_link.STL" />
      </geometry>
    </collision>
  </link>
  <joint
    name="base_link_joint"
    type="fixed">
    <origin
      xyz="0 0 0.3"
      rpy="0 0 0" />
    <parent
      link="base_footprint_link" />
    <child
      link="base_link" />
    <axis
      xyz="0 0 0" />
  </joint>
  <link
    name="FR1_link">
    <inertial>
      <origin
        xyz="0.024784 -1.0469E-05 -2.2229E-05"
        rpy="0 0 0" />
      <mass
        value="0.067553" />
      <inertia
        ixx="1.2584E-05"
        ixy="9.7813E-08"
        ixz="-1.6315E-08"
        iyy="1.514E-05"
        iyz="-4.0759E-09"
        izz="1.7075E-05" />
    </inertial>
    <visual>
      <origin
        xyz="0 0 0"
        rpy="0 0 0" />
      <geometry>
        <mesh
          filename="package://GRD_URDF_v8_material/meshes/FR1_link.STL" />
      </geometry>
      <material
        name="">
        <color
          rgba="0.89804 0.91765 0.92941 1" />
      </material>
    </visual>
    <collision>
      <origin
        xyz="0 0 0"
        rpy="0 0 0" />
      <geometry>
        <mesh
          filename="package://GRD_URDF_v8_material/meshes/FR1_link.STL" />
      </geometry>
    </collision>
  </link>
  <joint
    name="motor_front_right_hip"
    type="revolute">
    <origin
      xyz="0.1579 -0.0491 0.0385"
      rpy="0 0 0" />
    <parent
      link="base_link" />
    <child
      link="FR1_link" />
    <axis
      xyz="1 0 0" />
    <limit
      lower="-1.04"
      upper="1.04"
      effort="1000"
      velocity="0.7" />
  </joint>
  <link
    name="FR2_link">
    <inertial>
      <origin
        xyz="4.3562E-06 -0.039485 -0.070702"
        rpy="0 0 0" />
      <mass
        value="0.39532" />
      <inertia
        ixx="0.0016371"
        ixy="-1.4579E-08"
        ixz="6.2884E-08"
        iyy="0.0017598"
        iyz="-2.364E-05"
        izz="0.00015914" />
    </inertial>
    <visual>
      <origin
        xyz="0 0 0"
        rpy="0 0 0" />
      <geometry>
        <mesh
          filename="package://GRD_URDF_v8_material/meshes/FR2_link.STL" />
      </geometry>
      <material
        name="">
        <color
          rgba="1 1 1 1" />
      </material>
    </visual>
    <collision>
      <origin
        xyz="0 0 0"
        rpy="0 0 0" />
      <geometry>
        <mesh
          filename="package://GRD_URDF_v8_material/meshes/FR2_link.STL" />
      </geometry>
    </collision>
  </link>
  <joint
    name="motor_front_right_upper_leg"
    type="revolute">
    <origin
      xyz="0.0361 -0.0233999999999976 0"
      rpy="0 0 0" />
    <parent
      link="FR1_link" />
    <child
      link="FR2_link" />
    <axis
      xyz="0 1 0" />
    <limit
      lower="-1.571"
      upper="2.59"
      effort="1000"
      velocity="0.7" />
  </joint>
  <link
    name="FR3_link">
    <inertial>
      <origin
        xyz="3.7529E-08 -0.0074017 -0.10236"
        rpy="0 0 0" />
      <mass
        value="0.090352" />
      <inertia
        ixx="0.00022227"
        ixy="1.0154E-11"
        ixz="2.7851E-10"
        iyy="0.00022376"
        iyz="1.6738E-08"
        izz="1.1523E-05" />
    </inertial>
    <visual>
      <origin
        xyz="0 0 0"
        rpy="0 0 0" />
      <geometry>
        <mesh
          filename="package://GRD_URDF_v8_material/meshes/FR3_link.STL" />
      </geometry>
      <material
        name="">
        <color
          rgba="1 1 1 1" />
      </material>
    </visual>
    <collision>
      <origin
        xyz="0 0 0"
        rpy="0 0 0" />
      <geometry>
        <mesh
          filename="package://GRD_URDF_v8_material/meshes/FR3_link.STL" />
      </geometry>
    </collision>
  </link>
  <joint
    name="motor_front_right_lower_leg"
    type="revolute">
    <origin
      xyz="0 -0.0413999999999994 -0.209999999999993"
      rpy="0 0 0" />
    <parent
      link="FR2_link" />
    <child
      link="FR3_link" />
    <axis
      xyz="0 -1 0" />
    <limit
      lower="-2.9"
      upper="1.671"
      effort="1000"
      velocity="0.7" />
  </joint>
  <link
    name="front_right_foot">
    <inertial>
      <origin
        xyz="-6.6613E-16 1.4433E-15 0.0015002"
        rpy="0 0 0" />
      <mass
        value="0.032571" />
      <inertia
        ixx="5.047E-06"
        ixy="-5.0734E-22"
        ixz="1.352E-22"
        iyy="5.0467E-06"
        iyz="-1.4225E-21"
        izz="5.3157E-06" />
    </inertial>
    <visual>
      <origin
        xyz="0 0 0"
        rpy="0 0 0" />
      <geometry>
        <mesh
          filename="package://GRD_URDF_v8_material/meshes/front_right_foot.STL" />
      </geometry>
      <material
        name="">
        <color
          rgba="0.29804 0.29804 0.29804 1" />
      </material>
    </visual>
    <collision>
      <origin
        xyz="0 0 0"
        rpy="0 0 0" />
      <geometry>
        <mesh
          filename="package://GRD_URDF_v8_material/meshes/front_right_foot.STL" />
      </geometry>
    </collision>
  </link>
  <joint
    name="front_right_leg_foot"
    type="fixed">
    <origin
      xyz="0 -0.00739999999999999 -0.198000586455477"
      rpy="0 0 0" />
    <parent
      link="FR3_link" />
    <child
      link="front_right_foot" />
    <axis
      xyz="0 0 0" />
  </joint>
  <link
    name="FL4_link">
    <inertial>
      <origin
        xyz="0.0247841447425314 1.04692997031988E-05 2.22286183791942E-05"
        rpy="0 0 0" />
      <mass
        value="0.0675532787220811" />
      <inertia
        ixx="1.25839581231577E-05"
        ixy="-9.78129344167742E-08"
        ixz="1.63152405935888E-08"
        iyy="1.5140307434958E-05"
        iyz="-4.07589457904991E-09"
        izz="1.70746458531424E-05" />
    </inertial>
    <visual>
      <origin
        xyz="0 0 0"
        rpy="0 0 0" />
      <geometry>
        <mesh
          filename="package://GRD_URDF_v8_material/meshes/FL4_link.STL" />
      </geometry>
      <material
        name="">
        <color
          rgba="0.898039215686275 0.917647058823529 0.929411764705882 1" />
      </material>
    </visual>
    <collision>
      <origin
        xyz="0 0 0"
        rpy="0 0 0" />
      <geometry>
        <mesh
          filename="package://GRD_URDF_v8_material/meshes/FL4_link.STL" />
      </geometry>
    </collision>
  </link>
  <joint
    name="motor_front_left_hip"
    type="revolute">
    <origin
      xyz="0.1579 0.0490999999999959 0.0387999999999899"
      rpy="0 0 0" />
    <parent
      link="base_link" />
    <child
      link="FL4_link" />
    <axis
      xyz="1 0 0" />
    <limit
      lower="-1.04"
      upper="1.04"
      effort="1000"
      velocity="0.7" />
  </joint>
  <link
    name="FL5_link">
    <inertial>
      <origin
        xyz="-4.35616069133227E-06 0.0394850128833005 -0.0707022962699911"
        rpy="0 0 0" />
      <mass
        value="0.395321397887757" />
      <inertia
        ixx="0.00163713814608113"
        ixy="-1.45788089578397E-08"
        ixz="-6.28841253115549E-08"
        iyy="0.00175975062383322"
        iyz="2.36404618665139E-05"
        izz="0.000159141442838076" />
    </inertial>
    <visual>
      <origin
        xyz="0 0 0"
        rpy="0 0 0" />
      <geometry>
        <mesh
          filename="package://GRD_URDF_v8_material/meshes/FL5_link.STL" />
      </geometry>
      <material
        name="">
        <color
          rgba="1 1 1 1" />
      </material>
    </visual>
    <collision>
      <origin
        xyz="0 0 0"
        rpy="0 0 0" />
      <geometry>
        <mesh
          filename="package://GRD_URDF_v8_material/meshes/FL5_link.STL" />
      </geometry>
    </collision>
  </link>
  <joint
    name="motor_front_left_upper_leg"
    type="revolute">
    <origin
      xyz="0.0360999999999954 0.0234000000000044 0"
      rpy="0 0 0" />
    <parent
      link="FL4_link" />
    <child
      link="FL5_link" />
    <axis
      xyz="0 -1 0" />
    <limit
      lower="-1.571"
      upper="2.59"
      effort="1000"
      velocity="0.7" />
  </joint>
  <link
    name="FL6_link">
    <inertial>
      <origin
        xyz="3.75285352793853E-08 0.00739826798017804 -0.102361671813913"
        rpy="0 0 0" />
      <mass
        value="0.0903520455444552" />
      <inertia
        ixx="0.000222269756294016"
        ixy="1.01536103196166E-11"
        ixz="2.78508257222559E-10"
        iyy="0.000223759447255601"
        iyz="1.67376488552958E-08"
        izz="1.15226778599831E-05" />
    </inertial>
    <visual>
      <origin
        xyz="0 0 0"
        rpy="0 0 0" />
      <geometry>
        <mesh
          filename="package://GRD_URDF_v8_material/meshes/FL6_link.STL" />
      </geometry>
      <material
        name="">
        <color
          rgba="1 1 1 1" />
      </material>
    </visual>
    <collision>
      <origin
        xyz="0 0 0"
        rpy="0 0 0" />
      <geometry>
        <mesh
          filename="package://GRD_URDF_v8_material/meshes/FL6_link.STL" />
      </geometry>
    </collision>
  </link>
  <joint
    name="motor_front_left_lower_leg"
    type="revolute">
    <origin
      xyz="0 0.0414000000000007 -0.209999999999995"
      rpy="0 0 0" />
    <parent
      link="FL5_link" />
    <child
      link="FL6_link" />
    <axis
      xyz="0 1 0" />
    <limit
      lower="-2.9"
      upper="1.671"
      effort="1000"
      velocity="0.7" />
  </joint>
  <link
    name="front_left_foot">
    <inertial>
      <origin
        xyz="2.77555756156289E-17 3.60822483003176E-16 0.00150018449078348"
        rpy="0 0 0" />
      <mass
        value="0.0325711189299211" />
      <inertia
        ixx="5.04695257424751E-06"
        ixy="-4.8959115759098E-24"
        ixz="-1.98212390450565E-21"
        iyy="5.04670813748758E-06"
        iyz="6.91248630705877E-22"
        izz="5.31572382785122E-06" />
    </inertial>
    <visual>
      <origin
        xyz="0 0 0"
        rpy="0 0 0" />
      <geometry>
        <mesh
          filename="package://GRD_URDF_v8_material/meshes/front_left_foot.STL" />
      </geometry>
      <material
        name="">
        <color
          rgba="0.298039215686275 0.298039215686275 0.298039215686275 1" />
      </material>
    </visual>
    <collision>
      <origin
        xyz="0 0 0"
        rpy="0 0 0" />
      <geometry>
        <mesh
          filename="package://GRD_URDF_v8_material/meshes/front_left_foot.STL" />
      </geometry>
    </collision>
  </link>
  <joint
    name="front_left_leg_foot"
    type="fixed">
    <origin
      xyz="0 0.00740000000000136 -0.198000586455477"
      rpy="0 0 0" />
    <parent
      link="FL6_link" />
    <child
      link="front_left_foot" />
    <axis
      xyz="0 0 0" />
  </joint>
  <link
    name="RR7_link">
    <inertial>
      <origin
        xyz="-0.0236063085699754 0.000631885494629253 6.84388656857493E-12"
        rpy="0 0 0" />
      <mass
        value="0.073619269309767" />
      <inertia
        ixx="1.46576594061014E-05"
        ixy="4.64656371603288E-08"
        ixz="-3.57441089268569E-08"
        iyy="1.73197677200056E-05"
        iyz="3.92112851912774E-10"
        izz="1.81046682669036E-05" />
    </inertial>
    <visual>
      <origin
        xyz="0 0 0"
        rpy="0 0 0" />
      <geometry>
        <mesh
          filename="package://GRD_URDF_v8_material/meshes/RR7_link.STL" />
      </geometry>
      <material
        name="">
        <color
          rgba="1 1 1 1" />
      </material>
    </visual>
    <collision>
      <origin
        xyz="0 0 0"
        rpy="0 0 0" />
      <geometry>
        <mesh
          filename="package://GRD_URDF_v8_material/meshes/RR7_link.STL" />
      </geometry>
    </collision>
  </link>
  <joint
    name="motor_back_right_hip"
    type="revolute">
    <origin
      xyz="-0.157900000000004 -0.0491000000000027 0.0384999999999962"
      rpy="0 0 0" />
    <parent
      link="base_link" />
    <child
      link="RR7_link" />
    <axis
      xyz="-1 0 0" />
    <limit
      lower="-1.04"
      upper="1.04"
      effort="1000"
      velocity="0.7" />
  </joint>
  <link
    name="RR8_link">
    <inertial>
      <origin
        xyz="4.35616069077716E-06 -0.0394850128832991 -0.0707022962699928"
        rpy="0 0 0" />
      <mass
        value="0.395321397887757" />
      <inertia
        ixx="0.00163713814608113"
        ixy="-1.45788089571798E-08"
        ixz="6.28841253106135E-08"
        iyy="0.00175975062383322"
        iyz="-2.36404618665226E-05"
        izz="0.000159141442838076" />
    </inertial>
    <visual>
      <origin
        xyz="0 0 0"
        rpy="0 0 0" />
      <geometry>
        <mesh
          filename="package://GRD_URDF_v8_material/meshes/RR8_link.STL" />
      </geometry>
      <material
        name="">
        <color
          rgba="1 1 1 1" />
      </material>
    </visual>
    <collision>
      <origin
        xyz="0 0 0"
        rpy="0 0 0" />
      <geometry>
        <mesh
          filename="package://GRD_URDF_v8_material/meshes/RR8_link.STL" />
      </geometry>
    </collision>
  </link>
  <joint
    name="motor_back_right_upper_leg"
    type="revolute">
    <origin
      xyz="-0.0128499999999998 -0.0230999999999985 0"
      rpy="0 0 0" />
    <parent
      link="RR7_link" />
    <child
      link="RR8_link" />
    <axis
      xyz="0 1 0" />
    <limit
      lower="-1.571"
      upper="2.59"
      effort="1000"
      velocity="0.7" />
  </joint>
  <link
    name="RR9_link">
    <inertial>
      <origin
        xyz="3.75285321152496E-08 -0.00740173201982233 -0.102361671813917"
        rpy="0 0 0" />
      <mass
        value="0.0903520455444551" />
      <inertia
        ixx="0.000222269756294015"
        ixy="1.01536103203937E-11"
        ixz="2.78508257250272E-10"
        iyy="0.0002237594472556"
        iyz="1.67376488552685E-08"
        izz="1.15226778599831E-05" />
    </inertial>
    <visual>
      <origin
        xyz="0 0 0"
        rpy="0 0 0" />
      <geometry>
        <mesh
          filename="package://GRD_URDF_v8_material/meshes/RR9_link.STL" />
      </geometry>
      <material
        name="">
        <color
          rgba="1 1 1 1" />
      </material>
    </visual>
    <collision>
      <origin
        xyz="0 0 0"
        rpy="0 0 0" />
      <geometry>
        <mesh
          filename="package://GRD_URDF_v8_material/meshes/RR9_link.STL" />
      </geometry>
    </collision>
  </link>
  <joint
    name="motor_back_right_lower_leg"
    type="revolute">
    <origin
      xyz="0 -0.0413999999999989 -0.209999999999994"
      rpy="0 0 0" />
    <parent
      link="RR8_link" />
    <child
      link="RR9_link" />
    <axis
      xyz="0 -1 0" />
    <limit
      lower="-2.9"
      upper="1.671"
      effort="1000"
      velocity="0.7" />
  </joint>
  <link
    name="back_right_foot">
    <inertial>
      <origin
        xyz="-7.11097847272413E-14 -0.242000000000003 0.00150018449077555"
        rpy="0 0 0" />
      <mass
        value="0.032571118929921" />
      <inertia
        ixx="5.0469525742475E-06"
        ixy="2.1327978782839E-21"
        ixz="-1.6668475799677E-21"
        iyy="5.04670813748758E-06"
        iyz="-1.71150747579276E-21"
        izz="5.31572382785121E-06" />
    </inertial>
    <visual>
      <origin
        xyz="0 0 0"
        rpy="0 0 0" />
      <geometry>
        <mesh
          filename="package://GRD_URDF_v8_material/meshes/back_right_foot.STL" />
      </geometry>
      <material
        name="">
        <color
          rgba="0.298039215686275 0.298039215686275 0.298039215686275 1" />
      </material>
    </visual>
    <collision>
      <origin
        xyz="0 0 0"
        rpy="0 0 0" />
      <geometry>
        <mesh
          filename="package://GRD_URDF_v8_material/meshes/back_right_foot.STL" />
      </geometry>
    </collision>
  </link>
  <joint
    name="back_right_leg_foot"
    type="fixed">
    <origin
      xyz="0 0.234600000000003 -0.198000586455473"
      rpy="0 0 0" />
    <parent
      link="RR9_link" />
    <child
      link="back_right_foot" />
    <axis
      xyz="0 0 0" />
  </joint>
  <link
    name="RL10_link">
    <inertial>
      <origin
        xyz="-0.0236063085699692 -0.00063188549463164 -6.82938428031576E-12"
        rpy="0 0 0" />
      <mass
        value="0.073619269309767" />
      <inertia
        ixx="1.46576594061014E-05"
        ixy="-4.64656371603235E-08"
        ixz="3.57441089268562E-08"
        iyy="1.73197677200056E-05"
        iyz="3.92112851920474E-10"
        izz="1.81046682669036E-05" />
    </inertial>
    <visual>
      <origin
        xyz="0 0 0"
        rpy="0 0 0" />
      <geometry>
        <mesh
          filename="package://GRD_URDF_v8_material/meshes/RL10_link.STL" />
      </geometry>
      <material
        name="">
        <color
          rgba="1 1 1 1" />
      </material>
    </visual>
    <collision>
      <origin
        xyz="0 0 0"
        rpy="0 0 0" />
      <geometry>
        <mesh
          filename="package://GRD_URDF_v8_material/meshes/RL10_link.STL" />
      </geometry>
    </collision>
  </link>
  <joint
    name="motor_back_left_hip"
    type="revolute">
    <origin
      xyz="-0.157900000000008 0.0491000000000026 0.0384999999999878"
      rpy="0 0 0" />
    <parent
      link="base_link" />
    <child
      link="RL10_link" />
    <axis
      xyz="-1 0 0" />
    <limit
      lower="-1.04"
      upper="1.04"
      effort="1000"
      velocity="0.7" />
  </joint>
  <link
    name="RL11_link">
    <inertial>
      <origin
        xyz="-4.35616068608646E-06 0.0394850128832992 -0.0707022962699932"
        rpy="0 0 0" />
      <mass
        value="0.395321397887756" />
      <inertia
        ixx="0.00163713814608113"
        ixy="-1.45788089564926E-08"
        ixz="-6.28841253096486E-08"
        iyy="0.00175975062383321"
        iyz="2.364046186652E-05"
        izz="0.000159141442838075" />
    </inertial>
    <visual>
      <origin
        xyz="0 0 0"
        rpy="0 0 0" />
      <geometry>
        <mesh
          filename="package://GRD_URDF_v8_material/meshes/RL11_link.STL" />
      </geometry>
      <material
        name="">
        <color
          rgba="1 1 1 0.3" />
      </material>
    </visual>
    <collision>
      <origin
        xyz="0 0 0"
        rpy="0 0 0" />
      <geometry>
        <mesh
          filename="package://GRD_URDF_v8_material/meshes/RL11_link.STL" />
      </geometry>
    </collision>
  </link>
  <joint
    name="motor_back_left_upper_leg"
    type="revolute">
    <origin
      xyz="-0.0128500000000024 0.0230999999999986 0"
      rpy="0 0 0" />
    <parent
      link="RL10_link" />
    <child
      link="RL11_link" />
    <axis
      xyz="0 -1 0" />
    <limit
      lower="-1.571"
      upper="2.59"
      effort="1000"
      velocity="0.7" />
  </joint>
  <link
    name="RL12_link">
    <inertial>
      <origin
        xyz="3.75285400533443E-08 0.00739826798017364 -0.10236167181392"
        rpy="0 0 0" />
      <mass
        value="0.090352045544455" />
      <inertia
        ixx="0.000222269756294015"
        ixy="1.01536103178863E-11"
        ixz="2.78508257228715E-10"
        iyy="0.0002237594472556"
        iyz="1.67376488553293E-08"
        izz="1.15226778599831E-05" />
    </inertial>
    <visual>
      <origin
        xyz="0 0 0"
        rpy="0 0 0" />
      <geometry>
        <mesh
          filename="package://GRD_URDF_v8_material/meshes/RL12_link.STL" />
      </geometry>
      <material
        name="">
        <color
          rgba="1 1 1 1" />
      </material>
    </visual>
    <collision>
      <origin
        xyz="0 0 0"
        rpy="0 0 0" />
      <geometry>
        <mesh
          filename="package://GRD_URDF_v8_material/meshes/RL12_link.STL" />
      </geometry>
    </collision>
  </link>
  <joint
    name="motor_back_left_lower_leg"
    type="revolute">
    <origin
      xyz="0 0.0414000000000018 -0.209999999999994"
      rpy="0 0 0" />
    <parent
      link="RL11_link" />
    <child
      link="RL12_link" />
    <axis
      xyz="0 1 0" />
    <limit
      lower="-2.9"
      upper="1.671"
      effort="1000"
      velocity="0.7" />
  </joint>
  <link
    name="back_left_foot">
    <inertial>
      <origin
        xyz="4.6074255521944E-15 -4.7045700668491E-15 0.00150018449077621"
        rpy="0 0 0" />
      <mass
        value="0.0325711189299211" />
      <inertia
        ixx="5.04695257424751E-06"
        ixy="3.22003305032137E-22"
        ixz="-6.305518543915E-22"
        iyy="5.04670813748758E-06"
        iyz="9.63773792640485E-22"
        izz="5.31572382785122E-06" />
    </inertial>
    <visual>
      <origin
        xyz="0 0 0"
        rpy="0 0 0" />
      <geometry>
        <mesh
          filename="package://GRD_URDF_v8_material/meshes/back_left_foot.STL" />
      </geometry>
      <material
        name="">
        <color
          rgba="0.298039215686275 0.298039215686275 0.298039215686275 1" />
      </material>
    </visual>
    <collision>
      <origin
        xyz="0 0 0"
        rpy="0 0 0" />
      <geometry>
        <mesh
          filename="package://GRD_URDF_v8_material/meshes/back_left_foot.STL" />
      </geometry>
    </collision>
  </link>
  <joint
    name="back_left_leg_foot"
    type="fixed">
    <origin
      xyz="0 0.00739999999999999 -0.198000586455477"
      rpy="0 0 0" />
    <parent
      link="RL12_link" />
    <child
      link="back_left_foot" />
    <axis
      xyz="0 0 0" />
  </joint>
</robot>